<?xml version='1.0'?>
<sdf version='1.4'>
  <model name="truck">
    <static>true</static>
    <link name='chassis'>
      <pose>0 0 0.75 0 0 0</pose>
      <collision name='collision'>
        <geometry>
          <box>
            <size>2.5 1.5 1.5</size>
          </box>
        </geometry>
      </collision>
      <visual name='visual'>
        <geometry>
          <box>
            <size>2.5 1.5 1.5</size>
          </box>
        </geometry>
        <material>
          <script>
            <uri>file://media/materials/scripts/gazebo.material</uri>
            <name>Gazebo/CeilingTiled</name>
          </script>
        </material>
      </visual>
      <visual name="target">
        <pose>0 0 0.77 0 0 0</pose>
        <cast_shadows>false</cast_shadows>
        <geometry>
          <plane>
            <normal>0 0 1</normal>
            <size>1.5 1.5</size>
          </plane>
        </geometry>
        <material>
          <script>
            <uri>file://models/truck/materials/scripts</uri>
            <uri>file://models/truck/materials/textures</uri>
            <name>Target/Image</name>
          </script>
        </material>
      </visual>
      <collision name='caster_collision'>
        <pose>-1.2 0 -0.75 0 0 0</pose>
        <geometry>
          <sphere>
            <radius>.05</radius>
          </sphere>
        </geometry>
        <surface>
          <friction>
            <ode>
              <mu>0</mu>
              <mu2>0</mu2>
              <slip1>1.0</slip1>
              <slip2>1.0</slip2>
            </ode>
          </friction>
        </surface>
      </collision>
      <visual name='caster_visual'>
        <pose>-1.2 0 -0.75 0 0 0</pose>
        <geometry>
          <sphere>
            <radius>.05</radius>
          </sphere>
        </geometry>
      </visual>
    </link>
    <link name="left_wheel">
      <pose>1.0 0.85 0.75 0 1.5707 1.5707</pose>
      <collision name="collision">
        <geometry>
          <cylinder>
            <radius>.75</radius>
            <length>.1</length>
          </cylinder>
        </geometry>
      </collision>
      <visual name="visual">
        <geometry>
          <cylinder>
            <radius>.75</radius>
            <length>.1</length>
          </cylinder>
        </geometry>
        <material>
          <script>
            <uri>file://media/materials/scripts/gazebo.material</uri>
            <name>Gazebo/CeilingTiled</name>
          </script>
        </material>
      </visual>
    </link>
    <link name="right_wheel">
      <pose>1.0 -0.85 0.75 0 1.5707 1.5707</pose>
      <collision name="collision">
        <geometry>
          <cylinder>
            <radius>.75</radius>
            <length>.1</length>
          </cylinder>
        </geometry>
      </collision>
      <visual name="visual">
        <geometry>
          <cylinder>
            <radius>.75</radius>
            <length>.1</length>
          </cylinder>
        </geometry>
        <material>
          <script>
            <uri>file://media/materials/scripts/gazebo.material</uri>
            <name>Gazebo/CeilingTiled</name>
          </script>
        </material>
      </visual>
    </link>
    <joint type="revolute" name="left_wheel_hinge">
      <pose>0 0 -0.03 0 0 0</pose>
      <child>left_wheel</child>
      <parent>chassis</parent>
      <axis>
        <xyz>0 1 0</xyz>
      </axis>
    </joint>
    <joint type="revolute" name="right_wheel_hinge">
      <pose>0 0 0.03 0 0 0</pose>
      <child>right_wheel</child>
      <parent>chassis</parent>
      <axis>
        <xyz>0 1 0</xyz>
      </axis>
    </joint>
    <plugin name='model_push' filename='libmodel_push.so' />
  </model>
</sdf>
